Workbook

Sheet INSTRUCTIONS
A1: Setup Procedure
A2: 1. SaveAs to project folder
A3: 2. On the PROJECT_SETTINGS tab set the project name in cell A3
A4: 3. On the PROJECT_SETTINGS tab adjust Non-Equip Multipliers as needed. The overall Non-Equip Multiplier should match local, or expected values. Should be confirmed on project-by-project basis.
A5: 4. On the PROJECT_SETTINGS tab set the project rounding in F3 (0 = no rounding, -1 = Tens place, -2 = Hundreds place, -3 = Thousands place, -4 = Ten Thousands place) THIS FUNCTION ROUNDS SO IT FOLLOW THE EXCEL ROUNDING RULES. IF YOU PICK A ROUNDING NUMBER LARGER THEN THE EQUIPMENT CATAGORY TOTAL YOU WILL GET 0.
A6: 5. On the PROJECT_SETTINGS tab set the project equipment discount percntage in H3
A7: 6. On the PROJECT_SETTINGS tab set the project contengency percentage in J3
A9: AV Tools Ribbon Tab
A10: Update PROJECT_EQUIPMENT_LIST
B11: Use this button to import the manufactures you need for your project from the PROJECT_EQUIPMENT_LIST database.
A12: Add New System Tab
B13: Use this button to either add a new tab from the template or copy and rename and existing system tab
A14: Update Summary Sheet
B15: Use this button to update the summary sheet. The summary sheet also auto updates on system add, system delete, publish estimate, or publish BoM
A16: Equipment Count
B17: Use this button to update the Equipment Report sheet. This will update to the current state of systems based on the equipment list counts multiplied by the summery sheet room count.
B18: THIS NEEDS TO BE RUN AFTER CHANGES TO SYSTEM TYPES OR ROOM COUNTS TO UPDATE THE EQUPMENT REPORT.
A19: Add Row
B20: Use this button to add a row with proper formating above the currently selected row for both the system tabs and the PROJECT_EQUIPMENT_LIST tab
A21: Publish Estimate
B22: Use this button to publish estimates. A form will allow for selection of systems to issue, publishing notes, itemized cost, and labor cost. All selected systems are edited for budget release and issuance sheet upadated.
A23: Publish BoM
B24: Use this button to publish BoM for bidding. A form will allow for selection of systems to issue and publishing notes. All selected systems are edited for bidding release and issuance sheet updated.
A26: System Tab Use
A27: 1. The tab name is used for the system name and field A3 should not be edited
A28: 2. Room numbers seperated by a coma shoud be entered in D2 to allow for automated quanity counting. If the system is across multiple rooms, for example a divisible training room, use a dash to separate the room numbers.
A30: Change Tracking
A31: 1. Add change name to Issuances tab in column A.
A32: 2. On the system tab in the row of the item that is changing select the change from the pulldown selector in column AE
A33: 3. On the system tab in the row of the item that is changing enter the old quanity in column AH
A34: 4. Revision List will update when publish for estimate or publish BoM is selected based on the issuance selected
A36: Notes | Q36: Init | R36: Date
A37: 1. Parameters on the PROJECT_SETTINGS tab affect all System tabs | Q37: DW | R37: 44426
A38: 2. The PROJECT_EQUIPMENT_LIST tab is simply a reference of equipment commonly used in the past, it is not intended to be a comprehensive, up-to-date database of equipment. | Q38: DW | R38: 44426
A39: 3. To update Master tab use the Update PROJECT_EQUIPMENT_LIST button in the ribbon | Q39: DW | R39: 44428
A40: 4. Turn off Document Auto-save for macros to work properly | Q40: MLP | R40: 44426
A41: 5. Adding row to Master Tab: Macro "Add Row" will add a row above the current selected cell | Q41: DW | R41: 44427
A42: 6. Using Add Row macro: Make sure the device ID in the column A of the System Tempate is blank | Q42: MLP | R42: 44426
A43: 7. Summary Tab: always check (and extend) the calculations include all systems | Q43: MLP | R43: 44426
A44: 8. Summary tab: always check system numbering, large number of system may require manually revision | Q44: MLP | R44: 44426
...

Sheet PROJECT_SETTINGS
A2: Project Name | C2: Non-Equip Brakeout Titles | D2: Non-Equip Breakout Mults | F2: Rounding Variable | H2: Discount from MSRP | J2: Contingency | L2: Auto Archive and Issue Folders | N2: Ignore Hidden Tabs
A3: [PROJECT NAME] | C3: ENGINEERING | D3: 0.02 | F3: 0 | H3: 0 | J3: 0 | L3: FALSE | N3: FALSE
C4: PROJECT MANAGEMENT | D4: 0.02
C5: PRE-INSTALLATION & RACK FABRICATION | D5: 0.02 | F5: Rounding Varible Equivalents
C6: INSTALLATION | D6: 0.08 | F6: 0 = No Rounding
C7: PROGRAMMING | D7: 0.08 | F7: -1 = 10s place
C8: TAX | D8: 0.08275 | F8: -2 = 100s place
C9: G&A | D9: 0.1 | F9: -3 = 1,000s place
F10: -4 = 10,000s place
C11: TOTAL NON-EQUIP MULT - SHOULD BE APPROX. 40% | D11: =SUM(D3:D9) -> 0.40275

Sheet PROJECT_EQUIPMENT_LIST
A1: ITEM | B1: MFR | C1: MODEL | D1: DESCRIPTION | E1: NOTES | F1: MSRP | G1: MULT
B2: 1 Beyond | C2: 1BSRAM-VXP-S | D2: Automate VX Pro system | E2: Requires 1BSRAM-OPS | F2: 10995 | G2: 1
B3: 1 Beyond | C3: 1BSRAM-VXI-S | D3: Automate VX system | E3: Requires 1BSRAM-OPS | F3: 7995 | G3: 1
B4: 1 Beyond | C4: 1BSRAM-SLP-S | D4: Automate Select Pro system | F4: 7595 | G4: 1
B5: 1 Beyond | C5: 1BSRAM-SLI-S | D5: Automate Select system | F5: 5595 | G5: 1
A6: test01 | B6: 1 Beyond | C6: 1BSRAM-OPS | D6: Automate™ Professional Services, Required for all first time room designs. Includes design consultation, remote configuration and installation support and system verification. | F6: 2000 | G6: 1
B7: 1 Beyond | C7: 1BCAA3-N20 | D7: AutoTracker 3 with NDI® | E7: Includes Wall Mount | F7: 7595 | G7: 1
B8: 1 Beyond | C8: 1BCAA3-I20 | D8: AutoTracker 3 | E8: Includes Wall Mount | F8: 6995 | G8: 1
B9: 1 Beyond | C9: 1BCAFN-I12 | D9: AutoFinder | E9: Includes Wall Mount | F9: 6995 | G9: 1
B10: 1 Beyond | C10: 1BCAFR-112 | D10: AutoFramer | E10: Includes Wall Mount | F10: 3495 | G10: 1
B11: 1 Beyond | C11: 1BCAHK-I12 | D11: Hawk | F11: 6995 | G11: 1
B12: 1 Beyond | C12: 1BCAFL-IEP | D12: Falcon | E12: Includes Hawk Wall Mount | F12: 1995 | G12: 1
B13: 1 Beyond | C13: 1BCAPE-N20 | D13: PTZ-IP20 camera with HD-SDI,HDMI, NDI output, 20x zoom, and PoE+ | E13: Includes Wall Mount | F13: 2795 | G13: 1
B14: 1 Beyond | C14: 1BCAPE-I20 | D14: PTZ-IP20 camera with HD-SDI & HDMI output, 20x zoom, and PoE+ | E14: Includes Wall Mount | F14: 2495 | G14: 1
B15: 1 Beyond | C15: 1BCAPE-I12 | D15: PTZ-IP12 camera with HD-SDI & HDMI output, 12x zoom, and PoE+ | E15: Includes Wall Mount | F15: 2595 | G15: 1
B16: 1 Beyond | C16: 1BCAAC-JCI | D16: IP Joystick and keyboard control for 1 Beyond cameras | F16: 895 | G16: 1
B17: 1 Beyond | C17: 1BCAAC-AML | D17: MicLocater unit to be used with AutoFinder camera for locating handheld microphones. | F17: 795 | G17: 1
B18: 1 Beyond | C18: 1BCAAC-JC | D18: RS-485 Joystick and keyboard control for 1 Beyond cameras | F18: 595 | G18: 1
B19: 1 Beyond | C19: 1BCAAC-RPK | D19: Required Remote Power Kit for installs where power needs to travel more than 10 ft | F19: 120 | G19: 1
B20: 1 Beyond | C20: 1BCAAC-MCJ | D20: J shaped ceiling mount for AutoTracker or PTZ cameras | F20: 135 | G20: 1
B21: 1 Beyond | C21: 1BCAAC-MW | D21: Wall mount for PTZ and AutoTracker cameras | F21: 69 | G21: 1
B22: 1 Beyond | C22: 1BCAAC-MWS | D22: Wall mount shelf for PTZ and AutoTracker cameras | F22: 59 | G22: 1
B23: 1 Beyond | C23: 1BCAAC-MCP | D23: Ceiling plate- Mount for inverting standard PTZ cameras with image flip | F23: 49 | G23: 1
B24: 1 Beyond | C24: 1BCAAC-TTP | D24: Tall tripod, ideal for AutoTracker and PTZ cameras | F24: 295 | G24: 1
B25: Absen | C25: Acclaim 1.2 Pro | D25: P1.27mm,Wall Mounting,600nit in. display | E25: 4X4 | F25: 68169 | G25: 1
B26: Absen | C26: Acclaim 1.2 Plus | D26: P1.27mm,Wall Mounting,600nit in. display | E26: 4X4 | F26: 60739 | G26: 1
B27: Absen | C27: Acclaim 1.5 Pro | D27: P1.58mm,Wall Mounting,600nit in. display | E27: 4X4 | F27: 61189 | G27: 1
B28: Absen | C28: Acclaim 1.5 Plus | D28: P1.58mm,Wall Mounting,600nit in. display | E28: 4X4 | F28: 43459 | G28: 1
B29: Absen | C29: Acclaim 1.9 Plus | D29: P1.906mm,Wall Mounting,800nit in. display | E29: 4X4 | F29: 38579 | G29: 1
B30: Absen | C30: Acclaim 2.5 Plus | D30: P2.54mm,Wall Mounting,1000nit in. display | E30: 4X4 | F30: 24439 | G30: 1
B31: Absen | C31: Acclaim 1.2 Pro | D31: P1.27mm,Wall Mounting,600nit in. display | E31: 5X5 | F31: 103032 | G31: 1
B32: Absen | C32: Acclaim 1.2 Plus | D32: P1.27mm,Wall Mounting,600nit in. display | E32: 5X5 | F32: 91912 | G32: 1
B33: Absen | C33: Acclaim 1.5 Pro | D33: P1.58mm,Wall Mounting,600nit in. display | E33: 5X5 | F33: 90762 | G33: 1
B34: Absen | C34: Acclaim 1.5 Plus | D34: P1.58mm,Wall Mounting,600nit in. display | E34: 5X5 | F34: 63762 | G34: 1
B35: Absen | C35: Acclaim 1.9 Plus | D35: P1.906mm,Wall Mounting,800nit in. display | E35: 5X5 | F35: 56362 | G35: 1
B36: Absen | C36: Acclaim 2.5 Plus | D36: P2.54mm,Wall Mounting,1000nit in. display | E36: 5X5 | F36: 34662 | G36: 1
... B95: Absen | C95: C165 Wall mounted | D95: ABSENICON3.0 C165,Wall Mounting,350nit in. display | E95: 1 SET | F95: 68000 | G95: 1
B96: AJA | C96: UTAP-HDMI | D96: HDMI to USB Converter | F96: 250 | G96: 1
B97: APC | C97: SMTL1500RM3UC | D97: UPS and Surge/Spike Suppression - Shallow Depth- 1500VA | F97: 1875 | G97: 1
B98: APC | C98: SMTL1000RM2UC | D98: UPS and Surge/Spike Suppression - Shallow Depth- 1000VA | F98: 1450 | G98: 1
...

Sheet DATA_HOLD
A1: fdsaeW | B1: fdsaeW | D1: TRUE | AA1: TEMPLATE | AB1: 3.0.0
A2: 7TIR6FDUR | B2: 7TIR6FDUR | D2: FALSE | Z2: Autoarchive | AA2: No

Sheet SYSTEM_TEMPLATE_LOOKUP
A1: =PROJECT_SETTINGS!A3 -> [PROJECT NAME] | M1: ----------------------------------------------------------------------------------------------------------- Change Management --------------------------------------------------------------------------------------------------------------------------
A2: =MID(CELL("filename",A1),FIND("]",CELL("filename",A1))+1,255) -> SYSTEM_TEMPLATE_LOOKUP | C2: Room Numbers
A3: LAST ISSUED INFO
A4: ID | B4: DESCRIPTION | C4: MFR | D4: MODEL | E4: NOTES | F4: QTY | G4: UNIT COST | H4: EXTENDED COST | I4: SYSTEM SUBTOTAL | J4: MSRP | K4: MULT | M4: ISSUANCE | N4: MFR | O4: MODEL | P4: OLD QTY. | Q4: STATUS | R4: NEW QTY. | S4: SUMMARY
A5: DISPLAY | I5: =ROUND(SUM(H5:H8),PROJECT_SETTINGS!$F$3) -> 0
B6: =IF($A6="","",INDEX(PROJECT_EQUIPMENT_LIST!$A$2:$G$6633,MATCH($A6,PROJECT_EQUIPMENT_LIST!$A$2:$A$6633,0),4)) | C6: =IF($A6="","",INDEX(PROJECT_EQUIPMENT_LIST!$A$2:$G$6633,MATCH($A6,PROJECT_EQUIPMENT_LIST!$A$2:$A$6633,0),2)) | D6: =IF($A6="","",INDEX(PROJECT_EQUIPMENT_LIST!$A$2:$G$6633,MATCH($A6,PROJECT_EQUIPMENT_LIST!$A$2:$A$6633,0),3)) | E6: =IF($A6="","",IF(INDEX(PROJECT_EQUIPMENT_LIST!$A$2:$G$6633,MATCH($A6,PROJECT_EQUIPMENT_LIST!$A$2:$A$6633,0),5)<>"",INDEX(PROJECT_EQUIPMENT_LIST!$A$2:$G$6633,MATCH($A6,PROJECT_EQUIPMENT_LIST!$A$2:$A$6633,0),5),"")) | G6: =IF(ISNUMBER(J6)=TRUE,J6*K6,J6) | H6: =IF(ISNUMBER(G6)=TRUE,F6*G6,G6) | J6: =IF($A6="","",INDEX(PROJECT_EQUIPMENT_LIST!$A$2:$G$6633,MATCH($A6,PROJECT_EQUIPMENT_LIST!$A$2:$A$6633,0),6)) | K6: =IF($A6="","",INDEX(PROJECT_EQUIPMENT_LIST!$A$2:$G$6633,MATCH($A6,PROJECT_EQUIPMENT_LIST!$A$2:$A$6633,0),7)) | N6: =IF(ISBLANK(P6),"",C6) | O6: =IF(ISBLANK(P6),"",D6) | Q6: =IF(ISBLANK(P6),"",(CONCATENATE((IF(P6<R6,"Add","Delete"))," ","(",(ABS(P6-R6)),")"))) | R6: =IF(ISBLANK(P6),"",F6) | S6: =IF(ISBLANK(P6),"",CONCATENATE(Q6," ",N6, " Model: ",D6,";"," New Qty"," (",R6,")"))
B7: =IF($A7="","",INDEX(PROJECT_EQUIPMENT_LIST!$A$2:$G$6633,MATCH($A7,PROJECT_EQUIPMENT_LIST!$A$2:$A$6633,0),4)) | C7: =IF($A7="","",INDEX(PROJECT_EQUIPMENT_LIST!$A$2:$G$6633,MATCH($A7,PROJECT_EQUIPMENT_LIST!$A$2:$A$6633,0),2)) | D7: =IF($A7="","",INDEX(PROJECT_EQUIPMENT_LIST!$A$2:$G$6633,MATCH($A7,PROJECT_EQUIPMENT_LIST!$A$2:$A$6633,0),3)) | E7: =IF($A7="","",IF(INDEX(PROJECT_EQUIPMENT_LIST!$A$2:$G$6633,MATCH($A7,PROJECT_EQUIPMENT_LIST!$A$2:$A$6633,0),5)<>"",INDEX(PROJECT_EQUIPMENT_LIST!$A$2:$G$6633,MATCH($A7,PROJECT_EQUIPMENT_LIST!$A$2:$A$6633,0),5),"")) | G7: =IF(ISNUMBER(J7)=TRUE,J7*K7,J7) | H7: =IF(ISNUMBER(G7)=TRUE,F7*G7,G7) | J7: =IF($A7="","",INDEX(PROJECT_EQUIPMENT_LIST!$A$2:$G$6633,MATCH($A7,PROJECT_EQUIPMENT_LIST!$A$2:$A$6633,0),6)) | K7: =IF($A7="","",INDEX(PROJECT_EQUIPMENT_LIST!$A$2:$G$6633,MATCH($A7,PROJECT_EQUIPMENT_LIST!$A$2:$A$6633,0),7)) | N7: =IF(ISBLANK(P7),"",C7) | O7: =IF(ISBLANK(P7),"",D7) | Q7: =IF(ISBLANK(P7),"",(CONCATENATE((IF(P7<R7,"Add","Delete"))," ","(",(ABS(P7-R7)),")"))) | R7: =IF(ISBLANK(P7),"",F7) | S7: =IF(ISBLANK(P7),"",CONCATENATE(Q7," ",N7, " Model: ",D7,";"," New Qty"," (",R7,")"))
B8: =IF($A8="","",INDEX(PROJECT_EQUIPMENT_LIST!$A$2:$G$6633,MATCH($A8,PROJECT_EQUIPMENT_LIST!$A$2:$A$6633,0),4)) | C8: =IF($A8="","",INDEX(PROJECT_EQUIPMENT_LIST!$A$2:$G$6633,MATCH($A8,PROJECT_EQUIPMENT_LIST!$A$2:$A$6633,0),2)) | D8: =IF($A8="","",INDEX(PROJECT_EQUIPMENT_LIST!$A$2:$G$6633,MATCH($A8,PROJECT_EQUIPMENT_LIST!$A$2:$A$6633,0),3)) | E8: =IF($A8="","",IF(INDEX(PROJECT_EQUIPMENT_LIST!$A$2:$G$6633,MATCH($A8,PROJECT_EQUIPMENT_LIST!$A$2:$A$6633,0),5)<>"",INDEX(PROJECT_EQUIPMENT_LIST!$A$2:$G$6633,MATCH($A8,PROJECT_EQUIPMENT_LIST!$A$2:$A$6633,0),5),"")) | G8: =IF(ISNUMBER(J8)=TRUE,J8*K8,J8) | H8: =IF(ISNUMBER(G8)=TRUE,F8*G8,G8) | J8: =IF($A8="","",INDEX(PROJECT_EQUIPMENT_LIST!$A$2:$G$6633,MATCH($A8,PROJECT_EQUIPMENT_LIST!$A$2:$A$6633,0),6)) | K8: =IF($A8="","",INDEX(PROJECT_EQUIPMENT_LIST!$A$2:$G$6633,MATCH($A8,PROJECT_EQUIPMENT_LIST!$A$2:$A$6633,0),7)) | N8: =IF(ISBLANK(P8),"",C8) | O8: =IF(ISBLANK(P8),"",D8) | Q8: =IF(ISBLANK(P8),"",(CONCATENATE((IF(P8<R8,"Add","Delete"))," ","(",(ABS(P8-R8)),")"))) | R8: =IF(ISBLANK(P8),"",F8) | S8: =IF(ISBLANK(P8),"",CONCATENATE(Q8," ",N8, " Model: ",D8,";"," New Qty"," (",R8,")"))
A9: AUDIO | I9: =ROUND(SUM(H9:H12),PROJECT_SETTINGS!$F$3) -> 0
B10: =IF($A10="","",INDEX(PROJECT_EQUIPMENT_LIST!$A$2:$G$6633,MATCH($A10,PROJECT_EQUIPMENT_LIST!$A$2:$A$6633,0),4)) | C10: =IF($A10="","",INDEX(PROJECT_EQUIPMENT_LIST!$A$2:$G$6633,MATCH($A10,PROJECT_EQUIPMENT_LIST!$A$2:$A$6633,0),2)) | D10: =IF($A10="","",INDEX(PROJECT_EQUIPMENT_LIST!$A$2:$G$6633,MATCH($A10,PROJECT_EQUIPMENT_LIST!$A$2:$A$6633,0),3)) | E10: =IF($A10="","",IF(INDEX(PROJECT_EQUIPMENT_LIST!$A$2:$G$6633,MATCH($A10,PROJECT_EQUIPMENT_LIST!$A$2:$A$6633,0),5)<>"",INDEX(PROJECT_EQUIPMENT_LIST!$A$2:$G$6633,MATCH($A10,PROJECT_EQUIPMENT_LIST!$A$2:$A$6633,0),5),"")) | G10: =IF(ISNUMBER(J10)=TRUE,J10*K10,J10) | H10: =IF(ISNUMBER(G10)=TRUE,F10*G10,G10) | J10: =IF($A10="","",INDEX(PROJECT_EQUIPMENT_LIST!$A$2:$G$6633,MATCH($A10,PROJECT_EQUIPMENT_LIST!$A$2:$A$6633,0),6)) | K10: =IF($A10="","",INDEX(PROJECT_EQUIPMENT_LIST!$A$2:$G$6633,MATCH($A10,PROJECT_EQUIPMENT_LIST!$A$2:$A$6633,0),7)) | N10: =IF(ISBLANK(P10),"",C10) | O10: =IF(ISBLANK(P10),"",D10) | Q10: =IF(ISBLANK(P10),"",(CONCATENATE((IF(P10<R10,"Add","Delete"))," ","(",(ABS(P10-R10)),")"))) | R10: =IF(ISBLANK(P10),"",F10) | S10: =IF(ISBLANK(P10),"",CONCATENATE(Q10," ",N10, " Model: ",D10,";"," New Qty"," (",R10,")"))
B11: =IF($A11="","",INDEX(PROJECT_EQUIPMENT_LIST!$A$2:$G$6633,MATCH($A11,PROJECT_EQUIPMENT_LIST!$A$2:$A$6633,0),4)) | C11: =IF($A11="","",INDEX(PROJECT_EQUIPMENT_LIST!$A$2:$G$6633,MATCH($A11,PROJECT_EQUIPMENT_LIST!$A$2:$A$6633,0),2)) | D11: =IF($A11="","",INDEX(PROJECT_EQUIPMENT_LIST!$A$2:$G$6633,MATCH($A11,PROJECT_EQUIPMENT_LIST!$A$2:$A$6633,0),3)) | E11: =IF($A11="","",IF(INDEX(PROJECT_EQUIPMENT_LIST!$A$2:$G$6633,MATCH($A11,PROJECT_EQUIPMENT_LIST!$A$2:$A$6633,0),5)<>"",INDEX(PROJECT_EQUIPMENT_LIST!$A$2:$G$6633,MATCH($A11,PROJECT_EQUIPMENT_LIST!$A$2:$A$6633,0),5),"")) | G11: =IF(ISNUMBER(J11)=TRUE,J11*K11,J11) | H11: =IF(ISNUMBER(G11)=TRUE,F11*G11,G11) | J11: =IF($A11="","",INDEX(PROJECT_EQUIPMENT_LIST!$A$2:$G$6633,MATCH($A11,PROJECT_EQUIPMENT_LIST!$A$2:$A$6633,0),6)) | K11: =IF($A11="","",INDEX(PROJECT_EQUIPMENT_LIST!$A$2:$G$6633,MATCH($A11,PROJECT_EQUIPMENT_LIST!$A$2:$A$6633,0),7)) | N11: =IF(ISBLANK(P11),"",C11) | O11: =IF(ISBLANK(P11),"",D11) | Q11: =IF(ISBLANK(P11),"",(CONCATENATE((IF(P11<R11,"Add","Delete"))," ","(",(ABS(P11-R11)),")"))) | R11: =IF(ISBLANK(P11),"",F11) | S11: =IF(ISBLANK(P11),"",CONCATENATE(Q11," ",N11, " Model: ",D11,";"," New Qty"," (",R11,")"))
B12: =IF($A12="","",INDEX(PROJECT_EQUIPMENT_LIST!$A$2:$G$6633,MATCH($A12,PROJECT_EQUIPMENT_LIST!$A$2:$A$6633,0),4)) | C12: =IF($A12="","",INDEX(PROJECT_EQUIPMENT_LIST!$A$2:$G$6633,MATCH($A12,PROJECT_EQUIPMENT_LIST!$A$2:$A$6633,0),2)) | D12: =IF($A12="","",INDEX(PROJECT_EQUIPMENT_LIST!$A$2:$G$6633,MATCH($A12,PROJECT_EQUIPMENT_LIST!$A$2:$A$6633,0),3)) | E12: =IF($A12="","",IF(INDEX(PROJECT_EQUIPMENT_LIST!$A$2:$G$6633,MATCH($A12,PROJECT_EQUIPMENT_LIST!$A$2:$A$6633,0),5)<>"",INDEX(PROJECT_EQUIPMENT_LIST!$A$2:$G$6633,MATCH($A12,PROJECT_EQUIPMENT_LIST!$A$2:$A$6633,0),5),"")) | G12: =IF(ISNUMBER(J12)=TRUE,J12*K12,J12) | H12: =IF(ISNUMBER(G12)=TRUE,F12*G12,G12) | J12: =IF($A12="","",INDEX(PROJECT_EQUIPMENT_LIST!$A$2:$G$6633,MATCH($A12,PROJECT_EQUIPMENT_LIST!$A$2:$A$6633,0),6)) | K12: =IF($A12="","",INDEX(PROJECT_EQUIPMENT_LIST!$A$2:$G$6633,MATCH($A12,PROJECT_EQUIPMENT_LIST!$A$2:$A$6633,0),7)) | N12: =IF(ISBLANK(P12),"",C12) | O12: =IF(ISBLANK(P12),"",D12) | Q12: =IF(ISBLANK(P12),"",(CONCATENATE((IF(P12<R12,"Add","Delete"))," ","(",(ABS(P12-R12)),")"))) | R12: =IF(ISBLANK(P12),"",F12) | S12: =IF(ISBLANK(P12),"",CONCATENATE(Q12," ",N12, " Model: ",D12,";"," New Qty"," (",R12,")"))
A13: VIDEO | I13: =ROUND(SUM(H13:H16),PROJECT_SETTINGS!$F$3) -> 0
B14: =IF($A14="","",INDEX(PROJECT_EQUIPMENT_LIST!$A$2:$G$6633,MATCH($A14,PROJECT_EQUIPMENT_LIST!$A$2:$A$6633,0),4)) | C14: =IF($A14="","",INDEX(PROJECT_EQUIPMENT_LIST!$A$2:$G$6633,MATCH($A14,PROJECT_EQUIPMENT_LIST!$A$2:$A$6633,0),2)) | D14: =IF($A14="","",INDEX(PROJECT_EQUIPMENT_LIST!$A$2:$G$6633,MATCH($A14,PROJECT_EQUIPMENT_LIST!$A$2:$A$6633,0),3)) | E14: =IF($A14="","",IF(INDEX(PROJECT_EQUIPMENT_LIST!$A$2:$G$6633,MATCH($A14,PROJECT_EQUIPMENT_LIST!$A$2:$A$6633,0),5)<>"",INDEX(PROJECT_EQUIPMENT_LIST!$A$2:$G$6633,MATCH($A14,PROJECT_EQUIPMENT_LIST!$A$2:$A$6633,0),5),"")) | G14: =IF(ISNUMBER(J14)=TRUE,J14*K14,J14) | H14: =IF(ISNUMBER(G14)=TRUE,F14*G14,G14) | J14: =IF($A14="","",INDEX(PROJECT_EQUIPMENT_LIST!$A$2:$G$6633,MATCH($A14,PROJECT_EQUIPMENT_LIST!$A$2:$A$6633,0),6)) | K14: =IF($A14="","",INDEX(PROJECT_EQUIPMENT_LIST!$A$2:$G$6633,MATCH($A14,PROJECT_EQUIPMENT_LIST!$A$2:$A$6633,0),7)) | N14: =IF(ISBLANK(P14),"",C14) | O14: =IF(ISBLANK(P14),"",D14) | Q14: =IF(ISBLANK(P14),"",(CONCATENATE((IF(P14<R14,"Add","Delete"))," ","(",(ABS(P14-R14)),")"))) | R14: =IF(ISBLANK(P14),"",F14) | S14: =IF(ISBLANK(P14),"",CONCATENATE(Q14," ",N14, " Model: ",D14,";"," New Qty"," (",R14,")"))
B15: =IF($A15="","",INDEX(PROJECT_EQUIPMENT_LIST!$A$2:$G$6633,MATCH($A15,PROJECT_EQUIPMENT_LIST!$A$2:$A$6633,0),4)) | C15: =IF($A15="","",INDEX(PROJECT_EQUIPMENT_LIST!$A$2:$G$6633,MATCH($A15,PROJECT_EQUIPMENT_LIST!$A$2:$A$6633,0),2)) | D15: =IF($A15="","",INDEX(PROJECT_EQUIPMENT_LIST!$A$2:$G$6633,MATCH($A15,PROJECT_EQUIPMENT_LIST!$A$2:$A$6633,0),3)) | E15: =IF($A15="","",IF(INDEX(PROJECT_EQUIPMENT_LIST!$A$2:$G$6633,MATCH($A15,PROJECT_EQUIPMENT_LIST!$A$2:$A$6633,0),5)<>"",INDEX(PROJECT_EQUIPMENT_LIST!$A$2:$G$6633,MATCH($A15,PROJECT_EQUIPMENT_LIST!$A$2:$A$6633,0),5),"")) | G15: =IF(ISNUMBER(J15)=TRUE,J15*K15,J15) | H15: =IF(ISNUMBER(G15)=TRUE,F15*G15,G15) | J15: =IF($A15="","",INDEX(PROJECT_EQUIPMENT_LIST!$A$2:$G$6633,MATCH($A15,PROJECT_EQUIPMENT_LIST!$A$2:$A$6633,0),6)) | K15: =IF($A15="","",INDEX(PROJECT_EQUIPMENT_LIST!$A$2:$G$6633,MATCH($A15,PROJECT_EQUIPMENT_LIST!$A$2:$A$6633,0),7)) | N15: =IF(ISBLANK(P15),"",C15) | O15: =IF(ISBLANK(P15),"",D15) | Q15: =IF(ISBLANK(P15),"",(CONCATENATE((IF(P15<R15,"Add","Delete"))," ","(",(ABS(P15-R15)),")"))) | R15: =IF(ISBLANK(P15),"",F15) | S15: =IF(ISBLANK(P15),"",CONCATENATE(Q15," ",N15, " Model: ",D15,";"," New Qty"," (",R15,")"))
B16: =IF($A16="","",INDEX(PROJECT_EQUIPMENT_LIST!$A$2:$G$6633,MATCH($A16,PROJECT_EQUIPMENT_LIST!$A$2:$A$6633,0),4)) | C16: =IF($A16="","",INDEX(PROJECT_EQUIPMENT_LIST!$A$2:$G$6633,MATCH($A16,PROJECT_EQUIPMENT_LIST!$A$2:$A$6633,0),2)) | D16: =IF($A16="","",INDEX(PROJECT_EQUIPMENT_LIST!$A$2:$G$6633,MATCH($A16,PROJECT_EQUIPMENT_LIST!$A$2:$A$6633,0),3)) | E16: =IF($A16="","",IF(INDEX(PROJECT_EQUIPMENT_LIST!$A$2:$G$6633,MATCH($A16,PROJECT_EQUIPMENT_LIST!$A$2:$A$6633,0),5)<>"",INDEX(PROJECT_EQUIPMENT_LIST!$A$2:$G$6633,MATCH($A16,PROJECT_EQUIPMENT_LIST!$A$2:$A$6633,0),5),"")) | G16: =IF(ISNUMBER(J16)=TRUE,J16*K16,J16) | H16: =IF(ISNUMBER(G16)=TRUE,F16*G16,G16) | J16: =IF($A16="","",INDEX(PROJECT_EQUIPMENT_LIST!$A$2:$G$6633,MATCH($A16,PROJECT_EQUIPMENT_LIST!$A$2:$A$6633,0),6)) | K16: =IF($A16="","",INDEX(PROJECT_EQUIPMENT_LIST!$A$2:$G$6633,MATCH($A16,PROJECT_EQUIPMENT_LIST!$A$2:$A$6633,0),7)) | N16: =IF(ISBLANK(P16),"",C16) | O16: =IF(ISBLANK(P16),"",D16) | Q16: =IF(ISBLANK(P16),"",(CONCATENATE((IF(P16<R16,"Add","Delete"))," ","(",(ABS(P16-R16)),")"))) | R16: =IF(ISBLANK(P16),"",F16) | S16: =IF(ISBLANK(P16),"",CONCATENATE(Q16," ",N16, " Model: ",D16,";"," New Qty"," (",R16,")"))
A17: CONTROL | I17: =ROUND(SUM(H17:H20),PROJECT_SETTINGS!$F$3) -> 0
B18: =IF($A18="","",INDEX(PROJECT_EQUIPMENT_LIST!$A$2:$G$6633,MATCH($A18,PROJECT_EQUIPMENT_LIST!$A$2:$A$6633,0),4)) | C18: =IF($A18="","",INDEX(PROJECT_EQUIPMENT_LIST!$A$2:$G$6633,MATCH($A18,PROJECT_EQUIPMENT_LIST!$A$2:$A$6633,0),2)) | D18: =IF($A18="","",INDEX(PROJECT_EQUIPMENT_LIST!$A$2:$G$6633,MATCH($A18,PROJECT_EQUIPMENT_LIST!$A$2:$A$6633,0),3)) | E18: =IF($A18="","",IF(INDEX(PROJECT_EQUIPMENT_LIST!$A$2:$G$6633,MATCH($A18,PROJECT_EQUIPMENT_LIST!$A$2:$A$6633,0),5)<>"",INDEX(PROJECT_EQUIPMENT_LIST!$A$2:$G$6633,MATCH($A18,PROJECT_EQUIPMENT_LIST!$A$2:$A$6633,0),5),"")) | G18: =IF(ISNUMBER(J18)=TRUE,J18*K18,J18) | H18: =IF(ISNUMBER(G18)=TRUE,F18*G18,G18) | J18: =IF($A18="","",INDEX(PROJECT_EQUIPMENT_LIST!$A$2:$G$6633,MATCH($A18,PROJECT_EQUIPMENT_LIST!$A$2:$A$6633,0),6)) | K18: =IF($A18="","",INDEX(PROJECT_EQUIPMENT_LIST!$A$2:$G$6633,MATCH($A18,PROJECT_EQUIPMENT_LIST!$A$2:$A$6633,0),7)) | N18: =IF(ISBLANK(P18),"",C18) | O18: =IF(ISBLANK(P18),"",D18) | Q18: =IF(ISBLANK(P18),"",(CONCATENATE((IF(P18<R18,"Add","Delete"))," ","(",(ABS(P18-R18)),")"))) | R18: =IF(ISBLANK(P18),"",F18) | S18: =IF(ISBLANK(P18),"",CONCATENATE(Q18," ",N18, " Model: ",D18,";"," New Qty"," (",R18,")"))
B19: =IF($A19="","",INDEX(PROJECT_EQUIPMENT_LIST!$A$2:$G$6633,MATCH($A19,PROJECT_EQUIPMENT_LIST!$A$2:$A$6633,0),4)) | C19: =IF($A19="","",INDEX(PROJECT_EQUIPMENT_LIST!$A$2:$G$6633,MATCH($A19,PROJECT_EQUIPMENT_LIST!$A$2:$A$6633,0),2)) | D19: =IF($A19="","",INDEX(PROJECT_EQUIPMENT_LIST!$A$2:$G$6633,MATCH($A19,PROJECT_EQUIPMENT_LIST!$A$2:$A$6633,0),3)) | E19: =IF($A19="","",IF(INDEX(PROJECT_EQUIPMENT_LIST!$A$2:$G$6633,MATCH($A19,PROJECT_EQUIPMENT_LIST!$A$2:$A$6633,0),5)<>"",INDEX(PROJECT_EQUIPMENT_LIST!$A$2:$G$6633,MATCH($A19,PROJECT_EQUIPMENT_LIST!$A$2:$A$6633,0),5),"")) | G19: =IF(ISNUMBER(J19)=TRUE,J19*K19,J19) | H19: =IF(ISNUMBER(G19)=TRUE,F19*G19,G19) | J19: =IF($A19="","",INDEX(PROJECT_EQUIPMENT_LIST!$A$2:$G$6633,MATCH($A19,PROJECT_EQUIPMENT_LIST!$A$2:$A$6633,0),6)) | K19: =IF($A19="","",INDEX(PROJECT_EQUIPMENT_LIST!$A$2:$G$6633,MATCH($A19,PROJECT_EQUIPMENT_LIST!$A$2:$A$6633,0),7)) | N19: =IF(ISBLANK(P19),"",C19) | O19: =IF(ISBLANK(P19),"",D19) | Q19: =IF(ISBLANK(P19),"",(CONCATENATE((IF(P19<R19,"Add","Delete"))," ","(",(ABS(P19-R19)),")"))) | R19: =IF(ISBLANK(P19),"",F19) | S19: =IF(ISBLANK(P19),"",CONCATENATE(Q19," ",N19, " Model: ",D19,";"," New Qty"," (",R19,")"))
B20: =IF($A20="","",INDEX(PROJECT_EQUIPMENT_LIST!$A$2:$G$6633,MATCH($A20,PROJECT_EQUIPMENT_LIST!$A$2:$A$6633,0),4)) | C20: =IF($A20="","",INDEX(PROJECT_EQUIPMENT_LIST!$A$2:$G$6633,MATCH($A20,PROJECT_EQUIPMENT_LIST!$A$2:$A$6633,0),2)) | D20: =IF($A20="","",INDEX(PROJECT_EQUIPMENT_LIST!$A$2:$G$6633,MATCH($A20,PROJECT_EQUIPMENT_LIST!$A$2:$A$6633,0),3)) | E20: =IF($A20="","",IF(INDEX(PROJECT_EQUIPMENT_LIST!$A$2:$G$6633,MATCH($A20,PROJECT_EQUIPMENT_LIST!$A$2:$A$6633,0),5)<>"",INDEX(PROJECT_EQUIPMENT_LIST!$A$2:$G$6633,MATCH($A20,PROJECT_EQUIPMENT_LIST!$A$2:$A$6633,0),5),"")) | G20: =IF(ISNUMBER(J20)=TRUE,J20*K20,J20) | H20: =IF(ISNUMBER(G20)=TRUE,F20*G20,G20) | J20: =IF($A20="","",INDEX(PROJECT_EQUIPMENT_LIST!$A$2:$G$6633,MATCH($A20,PROJECT_EQUIPMENT_LIST!$A$2:$A$6633,0),6)) | K20: =IF($A20="","",INDEX(PROJECT_EQUIPMENT_LIST!$A$2:$G$6633,MATCH($A20,PROJECT_EQUIPMENT_LIST!$A$2:$A$6633,0),7)) | N20: =IF(ISBLANK(P20),"",C20) | O20: =IF(ISBLANK(P20),"",D20) | Q20: =IF(ISBLANK(P20),"",(CONCATENATE((IF(P20<R20,"Add","Delete"))," ","(",(ABS(P20-R20)),")"))) | R20: =IF(ISBLANK(P20),"",F20) | S20: =IF(ISBLANK(P20),"",CONCATENATE(Q20," ",N20, " Model: ",D20,";"," New Qty"," (",R20,")"))
A21: MISC. | I21: =ROUND(SUM(H21:H24),PROJECT_SETTINGS!$F$3) -> 0
B22: =IF($A22="","",INDEX(PROJECT_EQUIPMENT_LIST!$A$2:$G$6633,MATCH($A22,PROJECT_EQUIPMENT_LIST!$A$2:$A$6633,0),4)) | C22: =IF($A22="","",INDEX(PROJECT_EQUIPMENT_LIST!$A$2:$G$6633,MATCH($A22,PROJECT_EQUIPMENT_LIST!$A$2:$A$6633,0),2)) | D22: =IF($A22="","",INDEX(PROJECT_EQUIPMENT_LIST!$A$2:$G$6633,MATCH($A22,PROJECT_EQUIPMENT_LIST!$A$2:$A$6633,0),3)) | E22: =IF($A22="","",IF(INDEX(PROJECT_EQUIPMENT_LIST!$A$2:$G$6633,MATCH($A22,PROJECT_EQUIPMENT_LIST!$A$2:$A$6633,0),5)<>"",INDEX(PROJECT_EQUIPMENT_LIST!$A$2:$G$6633,MATCH($A22,PROJECT_EQUIPMENT_LIST!$A$2:$A$6633,0),5),"")) | G22: =IF(ISNUMBER(J22)=TRUE,J22*K22,J22) | H22: =IF(ISNUMBER(G22)=TRUE,F22*G22,G22) | J22: =IF($A22="","",INDEX(PROJECT_EQUIPMENT_LIST!$A$2:$G$6633,MATCH($A22,PROJECT_EQUIPMENT_LIST!$A$2:$A$6633,0),6)) | K22: =IF($A22="","",INDEX(PROJECT_EQUIPMENT_LIST!$A$2:$G$6633,MATCH($A22,PROJECT_EQUIPMENT_LIST!$A$2:$A$6633,0),7)) | N22: =IF(ISBLANK(P22),"",C22) | O22: =IF(ISBLANK(P22),"",D22) | Q22: =IF(ISBLANK(P22),"",(CONCATENATE((IF(P22<R22,"Add","Delete"))," ","(",(ABS(P22-R22)),")"))) | R22: =IF(ISBLANK(P22),"",F22) | S22: =IF(ISBLANK(P22),"",CONCATENATE(Q22," ",N22, " Model: ",D22,";"," New Qty"," (",R22,")"))
B23: =IF($A23="","",INDEX(PROJECT_EQUIPMENT_LIST!$A$2:$G$6633,MATCH($A23,PROJECT_EQUIPMENT_LIST!$A$2:$A$6633,0),4)) | C23: =IF($A23="","",INDEX(PROJECT_EQUIPMENT_LIST!$A$2:$G$6633,MATCH($A23,PROJECT_EQUIPMENT_LIST!$A$2:$A$6633,0),2)) | D23: =IF($A23="","",INDEX(PROJECT_EQUIPMENT_LIST!$A$2:$G$6633,MATCH($A23,PROJECT_EQUIPMENT_LIST!$A$2:$A$6633,0),3)) | E23: =IF($A23="","",IF(INDEX(PROJECT_EQUIPMENT_LIST!$A$2:$G$6633,MATCH($A23,PROJECT_EQUIPMENT_LIST!$A$2:$A$6633,0),5)<>"",INDEX(PROJECT_EQUIPMENT_LIST!$A$2:$G$6633,MATCH($A23,PROJECT_EQUIPMENT_LIST!$A$2:$A$6633,0),5),"")) | G23: =IF(ISNUMBER(J23)=TRUE,J23*K23,J23) | H23: =IF(ISNUMBER(G23)=TRUE,F23*G23,G23) | J23: =IF($A23="","",INDEX(PROJECT_EQUIPMENT_LIST!$A$2:$G$6633,MATCH($A23,PROJECT_EQUIPMENT_LIST!$A$2:$A$6633,0),6)) | K23: =IF($A23="","",INDEX(PROJECT_EQUIPMENT_LIST!$A$2:$G$6633,MATCH($A23,PROJECT_EQUIPMENT_LIST!$A$2:$A$6633,0),7)) | N23: =IF(ISBLANK(P23),"",C23) | O23: =IF(ISBLANK(P23),"",D23) | Q23: =IF(ISBLANK(P23),"",(CONCATENATE((IF(P23<R23,"Add","Delete"))," ","(",(ABS(P23-R23)),")"))) | R23: =IF(ISBLANK(P23),"",F23) | S23: =IF(ISBLANK(P23),"",CONCATENATE(Q23," ",N23, " Model: ",D23,";"," New Qty"," (",R23,")"))
B24: =IF($A24="","",INDEX(PROJECT_EQUIPMENT_LIST!$A$2:$G$6633,MATCH($A24,PROJECT_EQUIPMENT_LIST!$A$2:$A$6633,0),4)) | C24: =IF($A24="","",INDEX(PROJECT_EQUIPMENT_LIST!$A$2:$G$6633,MATCH($A24,PROJECT_EQUIPMENT_LIST!$A$2:$A$6633,0),2)) | D24: =IF($A24="","",INDEX(PROJECT_EQUIPMENT_LIST!$A$2:$G$6633,MATCH($A24,PROJECT_EQUIPMENT_LIST!$A$2:$A$6633,0),3)) | E24: =IF($A24="","",IF(INDEX(PROJECT_EQUIPMENT_LIST!$A$2:$G$6633,MATCH($A24,PROJECT_EQUIPMENT_LIST!$A$2:$A$6633,0),5)<>"",INDEX(PROJECT_EQUIPMENT_LIST!$A$2:$G$6633,MATCH($A24,PROJECT_EQUIPMENT_LIST!$A$2:$A$6633,0),5),"")) | G24: =IF(ISNUMBER(J24)=TRUE,J24*K24,J24) | H24: =IF(ISNUMBER(G24)=TRUE,F24*G24,G24) | J24: =IF($A24="","",INDEX(PROJECT_EQUIPMENT_LIST!$A$2:$G$6633,MATCH($A24,PROJECT_EQUIPMENT_LIST!$A$2:$A$6633,0),6)) | K24: =IF($A24="","",INDEX(PROJECT_EQUIPMENT_LIST!$A$2:$G$6633,MATCH($A24,PROJECT_EQUIPMENT_LIST!$A$2:$A$6633,0),7)) | N24: =IF(ISBLANK(P24),"",C24) | O24: =IF(ISBLANK(P24),"",D24) | Q24: =IF(ISBLANK(P24),"",(CONCATENATE((IF(P24<R24,"Add","Delete"))," ","(",(ABS(P24-R24)),")"))) | R24: =IF(ISBLANK(P24),"",F24) | S24: =IF(ISBLANK(P24),"",CONCATENATE(Q24," ",N24, " Model: ",D24,";"," New Qty"," (",R24,")"))
A25: // | D25: COST ESTIMATE SUMMARY
H26: TOTAL EQUIPMENT COST SUBTOTAL | I26: =SUM(I4:I24) -> 0
H27: DISCOUNT FROM MSRP | I27: =PROJECT_SETTINGS!H3 -> 0
H28: DISCOUNTED EQUIPMENT COST SUBTOTAL | I28: =I26*(1-I27) -> 0
H29: =PROJECT_SETTINGS!C3 -> ENGINEERING | I29: =I28*PROJECT_SETTINGS!$D$3 -> 0
H30: =PROJECT_SETTINGS!C4 -> PROJECT MANAGEMENT | I30: =I28*PROJECT_SETTINGS!$D$4 -> 0
H31: =PROJECT_SETTINGS!C5 -> PRE-INSTALLATION & RACK FABRICATION | I31: =I28*PROJECT_SETTINGS!$D$5 -> 0
H32: =PROJECT_SETTINGS!C6 -> INSTALLATION | I32: =I28*PROJECT_SETTINGS!$D$6 -> 0
H33: =PROJECT_SETTINGS!C7 -> PROGRAMMING | I33: =I28*PROJECT_SETTINGS!$D$7 -> 0
H34: =PROJECT_SETTINGS!C8 -> TAX | I34: =I28*PROJECT_SETTINGS!$D$8 -> 0
H35: =PROJECT_SETTINGS!C9 -> G&A | I35: =I28*PROJECT_SETTINGS!$D$9 -> 0
H36: TOTAL NON-EQUIPMENT COST SUBTOTAL | I36: =ROUND(SUM(I29:I35),PROJECT_SETTINGS!$F$3) -> 0
H37: CONTINGENCY PERCENTAGE | I37: =PROJECT_SETTINGS!J3 -> 0
H38: CONTINGENCY | I38: =(I28+I36)*I37 -> 0
H39: TOTAL INSTALLED COST | I39: =I28+I36+I38 -> 0

Sheet DWG Report
A1: System | B1: ID | C1: BOM Count | D1: Drawing Count

Sheet Equipment Report
A1: ID | B1: MFR | C1: MODEL | D1: QTY.

Sheet Issuances
A1: =Summary!A1 -> [PROJECT NAME] | C1: =NOW() -> 46112.778
A2: Issuance Log
A3: LAST ISSUED INFO
A4: ISSUANCE | B4: DATE | C4: SYSTEMS ISSUED

Sheet Summary
A1: =PROJECT_SETTINGS!A3 -> [PROJECT NAME] | L1: =NOW() -> 46112.778
A2: Audiovisual System Summary
A3: LAST ISSUED INFO
B4: SYSTEM NAME | C4: ROOM #'s | D4: EQUIPMENT | E4: DISCOUNT FROM MSRP | F4: DISCOUNT EQUIPMENT | G4: NON-EQUIPMENT | H4: CONTENGENCY % | I4: CONTENGENCY | J4: SYSTEM SUBTOTAL | K4: QTY | L4: SYSTEM EXTENDED
J5: =SUM(F5,G5,I5) -> 0 | L5: =J5*K5 -> 0
J6: =SUM(F6,G6,I6) -> 0 | L6: =J6*K6 -> 0
J7: =SUM(F7,G7,I7) -> 0 | L7: =J7*K7 -> 0
K9: TOTAL EQUIPMENT COST SUBTOTAL | L9: =SUMPRODUCT(F5:F7,K5:K7) -> 0
K11: TOTAL NON-EQUIPMENT COST SUBTOTAL | L11: =SUMPRODUCT(G5:G7,K5:K7) -> 0
K13: TOTAL CONTENGENCY SUBTOTAL | L13: =SUMPRODUCT(I5:I7,K5:K7) -> 0
K15: TOTAL INSTALLED COST | L15: =L9+L11+L13 -> 0

Sheet Revision List
A1: =Summary!A1 -> [PROJECT NAME] | H1: =NOW() -> 46112.778
A2: =MID(CELL("filename",A1),FIND("]",CELL("filename",A1))+1,255) -> Revision List
A3: LAST ISSUED INFO
A4: SYSTEM | B4: ISSUANCE | C4: MFR | D4: MODEL | E4: OLD QTY. | F4: STATUS | G4: NEW QTY | H4: SUMMARY

Sheet _TEMP
